<?xml version="1.0" encoding="utf-8"?>
<!-- =================================================================================== -->
<!-- |    This document was autogenerated by xacro from /home/ros/tictactoe_ws/src/tic_tac_toe/urdf/mh5l_d435i_pgn64_table.xacro | -->
<!-- |    EDITING THIS FILE BY HAND IS NOT RECOMMENDED                                 | -->
<!-- =================================================================================== -->
<robot name="robot_mh5l_d435i_pgn64_table">
  <!-- Properties -->
  <material name="yaskawa_white">
    <color rgba="0.9 0.9 0.9 1"/>
  </material>
  <!-- link list -->
  <link name="base_link">
    <visual>
      <origin rpy="0 0 0" xyz="0 0 0"/>
      <geometry>
        <mesh filename="package://motoman_mh5_support/meshes/mh5l/visual/base_link.stl"/>
      </geometry>
      <material name="yaskawa_white"/>
    </visual>
    <collision>
      <origin rpy="0 0 0" xyz="0 0 0"/>
      <geometry>
        <mesh filename="package://motoman_mh5_support/meshes/mh5l/collision/base_link.stl"/>
      </geometry>
    </collision>
  </link>
  <link name="link_1_s">
    <visual>
      <origin rpy="0 0 0" xyz="0 0 0"/>
      <geometry>
        <mesh filename="package://motoman_mh5_support/meshes/mh5l/visual/link_1_s.stl"/>
      </geometry>
      <material name="yaskawa_white"/>
    </visual>
    <collision>
      <origin rpy="0 0 0" xyz="0 0 0"/>
      <geometry>
        <mesh filename="package://motoman_mh5_support/meshes/mh5l/collision/link_1_s.stl"/>
      </geometry>
    </collision>
  </link>
  <link name="link_2_l">
    <visual>
      <origin rpy="0 0 0" xyz="0 0 0"/>
      <geometry>
        <mesh filename="package://motoman_mh5_support/meshes/mh5l/visual/link_2_l.stl"/>
      </geometry>
      <material name="yaskawa_white"/>
    </visual>
    <collision>
      <origin rpy="0 0 0" xyz="0 0 0"/>
      <geometry>
        <mesh filename="package://motoman_mh5_support/meshes/mh5l/collision/link_2_l.stl"/>
      </geometry>
    </collision>
  </link>
  <link name="link_3_u">
    <visual>
      <origin rpy="0 0 0" xyz="0 0 0"/>
      <geometry>
        <mesh filename="package://motoman_mh5_support/meshes/mh5l/visual/link_3_u.stl"/>
      </geometry>
      <material name="yaskawa_white"/>
    </visual>
    <collision>
      <origin rpy="0 0 0" xyz="0 0 0"/>
      <geometry>
        <mesh filename="package://motoman_mh5_support/meshes/mh5l/collision/link_3_u.stl"/>
      </geometry>
    </collision>
  </link>
  <link name="link_4_r">
    <visual>
      <origin rpy="0 0 0" xyz="0 0 0"/>
      <geometry>
        <mesh filename="package://motoman_mh5_support/meshes/mh5l/visual/link_4_r.stl"/>
      </geometry>
      <material name="yaskawa_white"/>
    </visual>
    <collision>
      <origin rpy="0 0 0" xyz="0 0 0"/>
      <geometry>
        <mesh filename="package://motoman_mh5_support/meshes/mh5l/collision/link_4_r.stl"/>
      </geometry>
    </collision>
  </link>
  <link name="link_5_b">
    <visual>
      <origin rpy="0 0 0" xyz="0 0 0"/>
      <geometry>
        <mesh filename="package://motoman_mh5_support/meshes/mh5l/visual/link_5_b.stl"/>
      </geometry>
      <material name="yaskawa_white"/>
    </visual>
    <collision>
      <origin rpy="0 0 0" xyz="0 0 0"/>
      <geometry>
        <mesh filename="package://motoman_mh5_support/meshes/mh5l/collision/link_5_b.stl"/>
      </geometry>
    </collision>
  </link>
  <link name="link_6_t">
    <visual>
      <origin rpy="0 0 0" xyz="0 0 0"/>
      <geometry>
        <mesh filename="package://motoman_mh5_support/meshes/mh5l/visual/link_6_t.stl"/>
      </geometry>
      <material name="yaskawa_white"/>
    </visual>
    <collision>
      <origin rpy="0 0 0" xyz="0 0 0"/>
      <geometry>
        <mesh filename="package://motoman_mh5_support/meshes/mh5l/collision/link_6_t.stl"/>
      </geometry>
    </collision>
  </link>
  <!-- end of link list -->
  <!-- joint list -->
  <joint name="joint_1_s" type="revolute">
    <parent link="base_link"/>
    <child link="link_1_s"/>
    <origin rpy="0 0 0" xyz="0 0 0.330"/>
    <axis xyz="0 0 1"/>
    <limit effort="303.8" lower="-2.96705972839" upper="2.96705972839" velocity="4.71238898038"/>
  </joint>
  <joint name="joint_2_l" type="revolute">
    <parent link="link_1_s"/>
    <child link="link_2_l"/>
    <origin rpy="0 0 0" xyz="0.0880 0 0.00"/>
    <axis xyz="0 1 0"/>
    <limit effort="205.8" lower="-1.1344640138" upper="2.61799387799" velocity="4.88692190558"/>
  </joint>
  <joint name="joint_3_u" type="revolute">
    <parent link="link_2_l"/>
    <child link="link_3_u"/>
    <origin rpy="0 0 0" xyz="0 0 0.400"/>
    <axis xyz="0 -1 0"/>
    <limit effort="85.5" lower="-1.2217304764" upper="3.31612557879" velocity="5.23598775598"/>
  </joint>
  <joint name="joint_4_r" type="revolute">
    <parent link="link_3_u"/>
    <child link="link_4_r"/>
    <origin rpy="0 0 0" xyz="0 0 0.040"/>
    <axis xyz="-1 0 0"/>
    <limit effort="44.7" lower="-3.31612557879" upper="3.31612557879" velocity="7.85398163397"/>
  </joint>
  <joint name="joint_5_b" type="revolute">
    <parent link="link_4_r"/>
    <child link="link_5_b"/>
    <origin rpy="0 0 0" xyz="0.405 0 0"/>
    <axis xyz="0 -1 0"/>
    <limit effort="18.0" lower="-2.35619449019" upper="2.35619449019" velocity="7.85398163397"/>
  </joint>
  <joint name="joint_6_t" type="revolute">
    <parent link="link_5_b"/>
    <child link="link_6_t"/>
    <origin rpy="0 0 0" xyz="0.080 0 0"/>
    <axis xyz="-1 0 0"/>
    <limit effort="18.0" lower="-6.28318530718" upper="6.28318530718" velocity="12.5663706144"/>
  </joint>
  <!-- end of joint list -->
  <!-- ROS base_link to Robot Manufacturer (Motoman) World Coordinates transform -->
  <link name="base"/>
  <joint name="base_link-base" type="fixed">
    <parent link="base_link"/>
    <child link="base"/>
    <origin rpy="0 0 0" xyz="0 0 0.330"/>
  </joint>
  <!-- ROS-Industrial 'flange' frame: attachment point for EEF models -->
  <link name="flange"/>
  <joint name="joint_6_t-flange" type="fixed">
    <parent link="link_6_t"/>
    <child link="flange"/>
    <origin rpy="0 0 0" xyz="0 0 0"/>
  </joint>
  <!-- ROS-Industrial 'tool0' frame: all-zeros tool frame -->
  <link name="tool0"/>
  <joint name="joint_6_t-tool0" type="fixed">
    <parent link="link_6_t"/>
    <child link="tool0"/>
    <origin rpy="3.14159265359 -1.57079632679 0" xyz="0 0 0"/>
  </joint>
  <!-- Schunk PGN64 EEF URDF -->
  <link name="eef_link">
    <visual>
      <origin rpy="0 0 0" xyz="0 0 0"/>
      <geometry>
        <mesh filename="package://schunk_pgn64_support/meshes/pgn64_closed_visual.stl"/>
      </geometry>
      <material name="eef">
        <color rgba="0.5 0.8 0.5 1"/>
      </material>
    </visual>
    <collision>
      <origin rpy="0 0 0" xyz="0 0 0"/>
      <geometry>
        <mesh filename="package://schunk_pgn64_support/meshes/pgn64_closed_collision.stl"/>
      </geometry>
    </collision>
  </link>
  <!-- EEF TCP Defined as the center point between EEF finger tips -->
  <joint name="eef_link-eef_tcp" type="fixed">
    <origin rpy="0 0 0" xyz="0 0 0.14152"/>
    <parent link="eef_link"/>
    <child link="eef_tcp"/>
  </joint>
  <link name="eef_tcp"/>
  <joint name="tool0-eef_link" type="fixed">
    <origin rpy="0 0 0" xyz="0 0 0"/>
    <parent link="tool0"/>
    <child link="eef_link"/>
  </joint>
  <!-- Motoman MH5L Table URDF -->
  <link name="table_link">
    <visual>
      <origin rpy="0 0 0" xyz="0 0 0"/>
      <geometry>
        <mesh filename="package://mh5l_table/meshes/mh5_worktable_visual.stl"/>
      </geometry>
      <material name="table">
        <color rgba="0.8 0.8 0.8 1"/>
      </material>
    </visual>
    <collision>
      <origin rpy="0 0 0" xyz="0 0 0"/>
      <geometry>
        <mesh filename="package://mh5l_table/meshes/mh5_worktable_collision.stl"/>
      </geometry>
    </collision>
  </link>
  <joint name="table_link-back_wall" type="fixed">
    <origin rpy="0 0 0" xyz="-0.9 0 0.4"/>
    <parent link="table_link"/>
    <child link="back_wall"/>
  </joint>
  <link name="back_wall">
    <visual>
      <origin rpy="0 0 0" xyz="0 0 0"/>
      <geometry>
        <box size="0.2 2 2.5"/>
      </geometry>
      <material name="table"/>
    </visual>
    <collision>
      <origin rpy="0 0 0" xyz="0 0 0"/>
      <geometry>
        <box size="0.2 2 2.5"/>
      </geometry>
    </collision>
  </link>
  <joint name="table_link-side_wall" type="fixed">
    <origin rpy="0 0 0" xyz="-0.1 -1.10 0"/>
    <parent link="table_link"/>
    <child link="side_wall"/>
  </joint>
  <link name="side_wall">
    <visual>
      <origin rpy="0 0 0" xyz="0 0 0"/>
      <geometry>
        <box size="0.80 0.40 1.7"/>
      </geometry>
      <material name="table"/>
    </visual>
    <collision>
      <origin rpy="0 0 0" xyz="0 0 0"/>
      <geometry>
        <box size="0.80 0.40 1.7"/>
      </geometry>
    </collision>
  </link>
  <joint name="base_link-table_link" type="fixed">
    <origin rpy="0 0 0" xyz="0 0 0"/>
    <parent link="base_link"/>
    <child link="table_link"/>
  </joint>
  <material name="aluminum">
    <color rgba="0.5 0.5 0.5 1"/>
  </material>
  <material name="plastic">
    <color rgba="0.1 0.1 0.1 1"/>
  </material>
  <!-- AIMS LAB Custom Camera Mount URDF -->
  <link name="mount_link">
    <visual>
      <origin rpy="0 0 0" xyz="0 0 0"/>
      <geometry>
        <mesh filename="package://tic_tac_toe/meshes/camera_mount.stl"/>
      </geometry>
      <material name="white">
        <color rgba="0.9 0.9 0.9 1"/>
      </material>
    </visual>
    <collision>
      <origin rpy="0 0 0" xyz="0 0 0"/>
      <geometry>
        <mesh filename="package://tic_tac_toe/meshes/camera_mount.stl"/>
      </geometry>
    </collision>
  </link>
  <link name="robot_mount"/>
  <!-- robot mount Defined as the center point between screw tips -->
  <joint name="robot_mount-mount_link" type="fixed">
    <origin rpy="0 0 0" xyz="-0.013 -0.0664 -0.0375"/>
    <parent link="robot_mount"/>
    <child link="mount_link"/>
  </joint>
  <link name="camera_base_link"/>
  <!-- camera body, with origin at bottom screw mount -->
  <joint name="camera_joint" type="fixed">
    <origin rpy="0 0 0" xyz="0 0 0"/>
    <parent link="camera_base_link"/>
    <child link="camera_bottom_screw_frame"/>
  </joint>
  <link name="camera_bottom_screw_frame"/>
  <joint name="camera_link_joint" type="fixed">
    <origin rpy="0 0 0" xyz="0.0106 0.0175 0.0125"/>
    <parent link="camera_bottom_screw_frame"/>
    <child link="camera_link"/>
  </joint>
  <link name="camera_link">
    <visual>
      <!-- the mesh origin is at front plate in between the two infrared camera axes -->
      <origin rpy="1.57079632679 0 1.57079632679" xyz="0.0043 -0.0175 0"/>
      <geometry>
        <mesh filename="package://realsense2_description/meshes/d435.dae"/>
      </geometry>
    </visual>
    <collision>
      <origin rpy="0 0 0" xyz="0 -0.0175 0"/>
      <geometry>
        <box size="0.02505 0.09 0.025"/>
      </geometry>
    </collision>
    <inertial>
      <!-- The following are not reliable values, and should not be used for modeling -->
      <mass value="0.072"/>
      <origin xyz="0 0 0"/>
      <inertia ixx="0.003881243" ixy="0.0" ixz="0.0" iyy="0.000498940" iyz="0.0" izz="0.003879257"/>
    </inertial>
  </link>
  <joint name="mount_link-camera_base_link" type="fixed">
    <origin rpy="-1.57079632679 0 -1.57079632679" xyz="0.03495 0.013 0.039"/>
    <parent link="mount_link"/>
    <child link="camera_base_link"/>
  </joint>
  <joint name="link_4_r-robot_mount" type="fixed">
    <!--origin xyz="0.33 0 -0.09" rpy="0 ${pi/2} 0"/-->
    <origin rpy="1.57079632679 0 0" xyz="0.31 0 -0.051 "/>
    <parent link="link_4_r"/>
    <child link="robot_mount"/>
  </joint>
</robot>

